Workbook
Name AccountList: Setup!$AA$2:$AA$3
Name CategoryList: Setup!$A$10:$A$28
Name Children: Setup!$P$2:$P$3
Name Debt: Setup!$V$2:$V$4
Name Entertainment: Setup!$R$2:$R$4
Name Food: Setup!$M$2:$M$4
Name Giving: Setup!$T$2:$T$3
Name Housing: Setup!$J$2:$J$7
Name Insurance: Setup!$N$2:$N$3
Name Legal: Setup!$Y$2
Name Medical: Setup!$O$2:$O$4
Name Miscellaneous: Setup!$Z$2:$Z$5
Name Personal_Care: Setup!$Q$2:$Q$4
Name Pets: Setup!$U$2
Name Savings: Setup!$W$2:$W$5
Name Subscriptions: Setup!$S$2:$S$5
Name Taxes: Setup!$X$2
Name Utilities: Setup!$K$2:$K$6
Name Vehicle: Setup!$L$2:$L$6

Sheet Instructions
A1: HOW TO USE THIS HOUSEHOLD BUDGET WORKBOOK
A3: Step | B3: What to do | C3: Where | D3: Important detail
A4: 1 | B4: Set the budget month and minimum checking buffer. | C4: Setup | D4: Use the first day of the month, such as 12/1/2020.
A5: 2 | B5: Enter up to seven income sources and choose each payment frequency. | C5: Setup | D5: Monthly Equivalent calculates automatically.
A6: 3 | B6: Enter planned amounts, priorities, due days, and fixed/variable status. | C6: Budget Plan | D6: Blue-font cells are intended for user input.
A7: 4 | B7: Paste a bank export into columns A:G without changing the headers. | C7: bk_download | D7: You may paste thousands of rows. Formulas in H:P standardize the data.
A8: 5 | B8: Review Budget Category, Subcategory, and Include? on imported transactions. | C8: bk_download | D8: Transfers and forecasted items default to No. Change misclassified items manually.
A9: 6 | B9: Filter by Month, Category, Account, or Include? to review transactions. | C9: bk_download | D9: Expense Amount converts bank negatives into positive spending.
A10: 7 | B10: Review actual spending, remaining budget, and category variance. | C10: Budget Plan / Monthly Summary | D10: Actuals are pulled directly from included bank transactions.
A11: 8 | B11: Enter debt balances, APRs, minimums, and due dates. | C11: Debts | D11: The selected strategy ranks debts and assigns available extra cash.
A12: 9 | B12: Enter savings goals and planned monthly contributions. | C12: Goals | D12: The sheet calculates required savings and feasibility.
A13: 10 | B13: Use the Dashboard for payment order and financial-health warnings. | C13: Dashboard | D13: Recommendations depend on the completeness of income, budget, debt, and goal inputs.
A15: Color | B15: Meaning
A16: Blue text | B16: User-entered assumptions or editable inputs
A17: Green text | B17: Formula linked to another worksheet
A18: Black text | B18: Formula or calculation
A19: Yellow fill | B19: Key setting that should be reviewed
A21: Bank Import Notes
A22: Supported structure | B22: The existing bank export uses status, date, transaction description, category, and amount.
A23: Different bank formats | B23: Rearrange the exported columns to match A:G or paste into the corresponding columns.
A24: Duplicates | B24: Possible duplicate rows are flagged in Review Note. Set Include? to No for any confirmed duplicate.
A25: MANUAL ACTUALS WORKFLOW
A26: 1 | B26: During the month | C26: Enter spending in Manual Actuals. Use positive expense amounts, select category/subcategory, and set Include? to Yes.
A27: 2 | B27: Live reporting | C27: Keep Setup!B8 set to Manual (Live). Dashboard and Budget Plan use manual entries immediately.
A28: 3 | B28: Month-end import | C28: Paste the bank export into bk_download and review the mapped categories and Include? flags.
A29: 4 | B29: Reconcile | C29: Use the Reconciliation sheet to compare manual entries against bank totals by category.
A30: 5 | B30: Close the month | C30: After differences are resolved, change Setup!B8 to Bank (Closed). Reports then use bank transactions as final actuals.
A31: 6 | B31: No double counting | C31: The source selector chooses manual OR bank actuals; it does not add them together.

Sheet Dashboard
A1: HOUSEHOLD FINANCIAL DASHBOARD
A3: ="Reporting Month: "&TEXT(Setup!B4,"mmmm yyyy")&" | Actuals: "&Setup!B8
A5: Monthly Income | D5: Planned Expenses | G5: Actual Expenses (Selected Source) | J5: Actual Cash Flow
A6: =Setup!H11 | D6: ='Budget Plan'!C57 | G6: ='Budget Plan'!D57 | J6: =B5-G6
A9: Planned Surplus | D9: Total Debt | G9: Goal Contributions | J9: Available for Extra Debt
A10: =B6-E6 | D10: =Debts!B14 | G10: =SUM(Goals!H4:H9) | J10: =MAX(0,B6-G6-K10)
A13: PAYMENT PRIORITY RECOMMENDATION | H13: Category | I13: Planned | J13: Actual | K13: Remaining
A14: Priority | B14: Action | C14: Amount ($) | D14: Timing | E14: Reason | F14: Status | H14: Housing | I14: =SUMIF('Monthly Summary'!$A$4:$A$20,H14,'Monthly Summary'!$B$4:$B$20) | J14: =SUMIF('Monthly Summary'!$A$4:$A$20,H14,'Monthly Summary'!$C$4:$C$20) | K14: =I14-J14
A15: 1 | B15: Cover all essential and fixed expenses | C15: =SUMIFS('Budget Plan'!$C$4:$C$55,'Budget Plan'!$G$4:$G$55,"Critical")+SUMIFS('Budget Plan'!$C$4:$C$55,'Budget Plan'!$H$4:$H$55,"Fixed") | D15: Before due dates | E15: Avoid missed bills and fees | F15: =IF(B6>=C15,"Funded","Shortfall") | H15: Utilities | I15: =SUMIF('Monthly Summary'!$A$4:$A$20,H15,'Monthly Summary'!$B$4:$B$20) | J15: =SUMIF('Monthly Summary'!$A$4:$A$20,H15,'Monthly Summary'!$C$4:$C$20) | K15: =I15-J15
A16: 2 | B16: Maintain checking buffer | C16: =Setup!B5 | D16: Throughout month | E16: Prevent overdraft | F16: =IF(B6-G6>=C16,"Protected","At Risk") | H16: Vehicle | I16: =SUMIF('Monthly Summary'!$A$4:$A$20,H16,'Monthly Summary'!$B$4:$B$20) | J16: =SUMIF('Monthly Summary'!$A$4:$A$20,H16,'Monthly Summary'!$C$4:$C$20) | K16: =I16-J16
A17: 3 | B17: Pay all debt minimums | C17: =Debts!B15 | D17: By due dates | E17: Protect credit and avoid penalties | F17: =IF(B6>=C15+C17,"Funded","Review") | H17: Food | I17: =SUMIF('Monthly Summary'!$A$4:$A$20,H17,'Monthly Summary'!$B$4:$B$20) | J17: =SUMIF('Monthly Summary'!$A$4:$A$20,H17,'Monthly Summary'!$C$4:$C$20) | K17: =I17-J17
A18: 4 | B18: Fund savings goals | C18: =SUM(Goals!H4:H9) | D18: After essentials | E18: Maintain goal progress | F18: =IF(B6-G6-C17>=C18,"Funded","Reduce/Delay") | H18: Debt | I18: =SUMIF('Monthly Summary'!$A$4:$A$20,H18,'Monthly Summary'!$B$4:$B$20) | J18: =SUMIF('Monthly Summary'!$A$4:$A$20,H18,'Monthly Summary'!$C$4:$C$20) | K18: =I18-J18
A19: 5 | B19: Send remaining surplus to top-ranked debt | C19: =MAX(0,B10-Setup!B5) | D19: After all above | E19: Reduce interest and payoff time | F19: =IF(C19>0,"Recommended","No extra available") | H19: Savings | I19: =SUMIF('Monthly Summary'!$A$4:$A$20,H19,'Monthly Summary'!$B$4:$B$20) | J19: =SUMIF('Monthly Summary'!$A$4:$A$20,H19,'Monthly Summary'!$C$4:$C$20) | K19: =I19-J19
H20: Entertainment | I20: =SUMIF('Monthly Summary'!$A$4:$A$20,H20,'Monthly Summary'!$B$4:$B$20) | J20: =SUMIF('Monthly Summary'!$A$4:$A$20,H20,'Monthly Summary'!$C$4:$C$20) | K20: =I20-J20
H21: Subscriptions | I21: =SUMIF('Monthly Summary'!$A$4:$A$20,H21,'Monthly Summary'!$B$4:$B$20) | J21: =SUMIF('Monthly Summary'!$A$4:$A$20,H21,'Monthly Summary'!$C$4:$C$20) | K21: =I21-J21
A22: FINANCIAL HEALTH FLAGS | H22: Miscellaneous | I22: =SUMIF('Monthly Summary'!$A$4:$A$20,H22,'Monthly Summary'!$B$4:$B$20) | J22: =SUMIF('Monthly Summary'!$A$4:$A$20,H22,'Monthly Summary'!$C$4:$C$20) | K22: =I22-J22
A23: Metric | B23: Current | C23: Target | D23: Status | E23: Recommended Action | F23: Notes
A24: Savings Rate | B24: =IF(B6=0,0,SUMIFS('Budget Plan'!$D$4:$D$55,'Budget Plan'!$A$4:$A$55,"Savings")/B6) | C24: 0.1 | D24: =IF(B24>=C24,"Healthy","Below target") | E24: Increase goal contributions if below target
A25: Debt Payment Ratio | B25: =IF(B6=0,0,Debts!B15/B6) | C25: 0.2 | D25: =IF(B25<=C25,"Healthy","High") | E25: Reduce debt burden if above target
A26: Housing Ratio | B26: =IF(B6=0,0,SUMIFS('Budget Plan'!$D$4:$D$55,'Budget Plan'!$A$4:$A$55,"Housing")/B6) | C26: 0.3 | D26: =IF(B26<=C26,"Healthy","High") | E26: Review housing costs if above target
A27: Emergency Fund Months | B27: =IF(SUMIFS('Budget Plan'!$D$4:$D$55,'Budget Plan'!$G$4:$G$55,"Critical")=0,0,Goals!D4/SUMIFS('Budget Plan'!$D$4:$D$55,'Budget Plan'!$G$4:$G$55,"Critical")) | C27: =Setup!B7 | D27: =IF(B27>=C27,"Healthy","Below target") | E27: Build emergency savings
A28: Budget Variance | B28: ='Budget Plan'!E57 | C28: 0 | D28: =IF(B28>=C28,"On budget","Over budget") | E28: Review categories over budget

Sheet Setup
A1: HOUSEHOLD BUDGET CONTROL CENTER | I1: Subcategory Lists → | J1: Housing | K1: Utilities | L1: Vehicle | M1: Food | N1: Insurance | O1: Medical | P1: Children | Q1: Personal Care | R1: Entertainment | S1: Subscriptions | T1: Giving | U1: Pets | V1: Debt | W1: Savings | X1: Taxes | Y1: Legal | Z1: Account → | AA1: Account
J2: Mortgage/Rent | K2: Electricity | L2: Car Payment | M2: Groceries | N2: Life Insurance | O2: Healthcare | P2: Child/Dependent | Q2: Personal Care | R2: Entertainment | S2: Streaming | T2: Tithe/Charity | U2: Pet Care | V2: Loans | W2: Emergency Fund | X2: Federal/State/Local | Y2: Legal | Z2: Cash/ATM | AA2: Checking
A3: Core Settings | B3: Value | D3: Income Source | E3: Owner | F3: Frequency | G3: Net Amount ($) | H3: Monthly Equivalent ($) | J3: Property Taxes | K3: Water/Sewer/Trash | L3: Auto Insurance | M3: Dining Out | N3: Disability/Other | O3: Prescriptions | P3: School/Activities | Q3: Clothing | R3: Online Services | S3: Music | T3: Gifts | V3: Credit Cards | W3: General Savings | Z3: General Merchandise | AA3: Savings
A4: Selected Budget Month | B4: August 2026 | D4: Income 1 | E4: Household | F4: Monthly | G4: 3938.58 | H4: =IF(G4="","",G4*IF(F4="Weekly",52/12,IF(F4="Biweekly",26/12,IF(F4="Semimonthly",2,IF(F4="Monthly",1,IF(F4="Quarterly",1/3,IF(F4="Annual",1/12,1))))))) | J4: Home Insurance | K4: Internet | L4: Fuel | M4: Household Supplies | O4: Dental/Vision | Q4: Hair/Nails | R4: Subscriptions | S4: Software/Apps | V4: Other Debt | W4: Retirement | Z4: Other
A5: Minimum Checking Buffer | B5: 500 | D5: Income 2 | E5: Household | F5: Monthly | G5: 758.37 | H5: 758.37 | J5: HOA | K5: Telephone | L5: Maintenance/Repairs | S5: Other Subscriptions | W5: College | Z5: Uncategorized
A6: Debt Strategy | B6: Avalanche | D6: Income 3 | E6: Household | F6: Monthly | G6: 2240 | H6: 2240 | J6: Home Maintenance | K6: Gas | L6: Registration/Tolls
A7: Emergency Fund Target (months) | B7: 3 | D7: Income 4 | E7: Household | F7: Monthly | G7: 4275.17 | H7: 4275.17 | J7: Home Improvement
A8: Actuals Source Mode | B8: Manual (Live) | D8: Income 5 | E8: Household | F8: Monthly | G8: 4078.45 | H8: 4078.45
A9: Budget Month Start Day | B9: 29 | D9: Income 6 | E9: Household | F9: Monthly | G9: 1752.78 | H9: 1752.78
A10: Budget Category | B10: Default Subcategory | C10: Active | D10: Income 7 | E10: Household | F10: Monthly | G10: 1752.78 | H10: 1752.78
A11: Housing | B11: Mortgage/Rent | C11: Yes | D11: Total Monthly Income | H11: =SUM(H4:H10)
A12: Utilities | B12: Electricity | C12: Yes
A13: Vehicle | B13: Car Payment | C13: Yes
A14: Food | B14: Groceries | C14: Yes | E14: Bank Category | F14: Budget Category | G14: Subcategory
A15: Insurance | B15: Home/Life/Other | C15: Yes | E15: Mortgages | F15: Housing | G15: Mortgage/Rent
A16: Medical | B16: Healthcare | C16: Yes | E16: Home Maintenance | F16: Housing | G16: Home Maintenance
A17: Children | B17: Child/Dependent | C17: Yes | E17: Home Improvement | F17: Housing | G17: Home Improvement
A18: Personal Care | B18: Personal Care | C18: Yes | E18: Century Link | F18: Utilities | G18: Internet
A19: Entertainment | B19: Subscriptions | C19: Yes | E19: Just Energy | F19: Utilities | G19: Electricity
A20: Subscriptions | B20: Streaming | C20: Yes | E20: Killeen Utilities | F20: Utilities | G20: Water/Sewer/Trash
A21: Giving | B21: Tithe/Charity | C21: Yes | E21: Telephone Services | F21: Utilities | G21: Telephone
A22: Pets | B22: Pet Care | C22: Yes | E22: Car Payment | F22: Vehicle | G22: Car Payment
A23: Debt | B23: Loans/Credit Cards | C23: Yes | E23: Automotive Expenses | F23: Vehicle | G23: Maintenance/Repairs
A24: Savings | B24: Savings/Investments | C24: Yes | E24: Gasoline/Fuel | F24: Vehicle | G24: Fuel
A25: Taxes | B25: Taxes | C25: Yes | E25: Groceries | F25: Food | G25: Groceries
... A29: Transfers | B29: Transfers | C29: No | E29: Child/Dependent Expenses | F29: Children | G29: Child/Dependent
E30: Clothing/Shoes | F30: Personal Care | G30: Clothing
E31: Personal Care | F31: Personal Care | G31: Personal Care
E32: Entertainment | F32: Entertainment | G32: Entertainment
E33: Online Services | F33: Entertainment | G33: Online Services
E34: Pets/Pet Care | F34: Pets | G34: Pet Care
E35: Loans | F35: Debt | G35: Loans
E36: ATM/Cash Withdrawals | F36: Miscellaneous | G36: Cash/ATM
E37: General Merchandise | F37: Miscellaneous | G37: General Merchandise
E38: Other Expenses | F38: Miscellaneous | G38: Other
E39: Uncategorized | F39: Miscellaneous | G39: Uncategorized
E40: Other Income | F40: Income | G40: Other Income
E41: Transfers | F41: Transfers | G41: Transfers
... E79: Utilities | F79: Utilities | G79: Electricity

Sheet Budget Plan
A1: MONTHLY BUDGET PLAN — LIVE ACTUALS & MONTH-END RECONCILIATION
A3: Category | B3: Subcategory | C3: Planned ($) | D3: Actual Used ($) | E3: Remaining ($) | F3: Variance % | G3: Priority | H3: Fixed/Variable | I3: Due Day | J3: Notes | K3: Manual Actual ($) | L3: Bank Actual ($) | M3: Recon Difference ($)
A4: Housing | B4: Mortgage/Rent | C4: =1396.87+767+406.91 | D4: =IF(Setup!$B$8="Bank (Closed)",L4,K4) | E4: =C4-D4 | F4: =IF(C4=0,IF(D4=0,0,-1),(C4-D4)/C4) | G4: Medium | H4: Fixed | K4: =SUMIFS('Manual Actuals'!$C$2:$C$861,'Manual Actuals'!$D$2:$D$861,$A4,'Manual Actuals'!$E$2:$E$861,$B4,'Manual Actuals'!$H$2:$H$861,Setup!$B$4,'Manual Actuals'!$G$2:$G$861,"Yes") | L4: =SUMIFS(bk_download!$L$2:$L$1902,bk_download!$H$2:$H$1902,$A4,bk_download!$I$2:$I$1902,$B4,bk_download!$K$2:$K$1902,Setup!$B$4,bk_download!$J$2:$J$1902,"Yes") | M4: =K4-L4
A5: Housing | B5: Property Taxes | C5: 0 | D5: =IF(Setup!$B$8="Bank (Closed)",L5,K5) | E5: =C5-D5 | F5: =IF(C5=0,IF(D5=0,0,-1),(C5-D5)/C5) | G5: Medium | H5: Variable | J5: Exempt due to status | K5: =SUMIFS('Manual Actuals'!$C$2:$C$861,'Manual Actuals'!$D$2:$D$861,$A5,'Manual Actuals'!$E$2:$E$861,$B5,'Manual Actuals'!$H$2:$H$861,Setup!$B$4,'Manual Actuals'!$G$2:$G$861,"Yes") | L5: =SUMIFS(bk_download!$L$2:$L$1902,bk_download!$H$2:$H$1902,$A5,bk_download!$I$2:$I$1902,$B5,bk_download!$K$2:$K$1902,Setup!$B$4,bk_download!$J$2:$J$1902,"Yes") | M5: =K5-L5
A6: Housing | B6: Home Insurance | C6: 0 | D6: =IF(Setup!$B$8="Bank (Closed)",L6,K6) | E6: =C6-D6 | F6: =IF(C6=0,IF(D6=0,0,-1),(C6-D6)/C6) | G6: Medium | H6: Variable | J6: Included in mortgage payment | K6: =SUMIFS('Manual Actuals'!$C$2:$C$861,'Manual Actuals'!$D$2:$D$861,$A6,'Manual Actuals'!$E$2:$E$861,$B6,'Manual Actuals'!$H$2:$H$861,Setup!$B$4,'Manual Actuals'!$G$2:$G$861,"Yes") | L6: =SUMIFS(bk_download!$L$2:$L$1902,bk_download!$H$2:$H$1902,$A6,bk_download!$I$2:$I$1902,$B6,bk_download!$K$2:$K$1902,Setup!$B$4,bk_download!$J$2:$J$1902,"Yes") | M6: =K6-L6
A7: Housing | B7: HOA | C7: 99 | D7: =IF(Setup!$B$8="Bank (Closed)",L7,K7) | E7: =C7-D7 | F7: =IF(C7=0,IF(D7=0,0,-1),(C7-D7)/C7) | G7: Medium | H7: Fixed | K7: =SUMIFS('Manual Actuals'!$C$2:$C$861,'Manual Actuals'!$D$2:$D$861,$A7,'Manual Actuals'!$E$2:$E$861,$B7,'Manual Actuals'!$H$2:$H$861,Setup!$B$4,'Manual Actuals'!$G$2:$G$861,"Yes") | L7: =SUMIFS(bk_download!$L$2:$L$1902,bk_download!$H$2:$H$1902,$A7,bk_download!$I$2:$I$1902,$B7,bk_download!$K$2:$K$1902,Setup!$B$4,bk_download!$J$2:$J$1902,"Yes") | M7: =K7-L7
A8: Housing | B8: Home Maintenance | C8: 0 | D8: =IF(Setup!$B$8="Bank (Closed)",L8,K8) | E8: =C8-D8 | F8: =IF(C8=0,IF(D8=0,0,-1),(C8-D8)/C8) | G8: Medium | H8: Variable | K8: =SUMIFS('Manual Actuals'!$C$2:$C$861,'Manual Actuals'!$D$2:$D$861,$A8,'Manual Actuals'!$E$2:$E$861,$B8,'Manual Actuals'!$H$2:$H$861,Setup!$B$4,'Manual Actuals'!$G$2:$G$861,"Yes") | L8: =SUMIFS(bk_download!$L$2:$L$1902,bk_download!$H$2:$H$1902,$A8,bk_download!$I$2:$I$1902,$B8,bk_download!$K$2:$K$1902,Setup!$B$4,bk_download!$J$2:$J$1902,"Yes") | M8: =K8-L8
A9: Housing | B9: Home Improvement | C9: 0 | D9: =IF(Setup!$B$8="Bank (Closed)",L9,K9) | E9: =C9-D9 | F9: =IF(C9=0,IF(D9=0,0,-1),(C9-D9)/C9) | G9: Medium | H9: Variable | K9: =SUMIFS('Manual Actuals'!$C$2:$C$861,'Manual Actuals'!$D$2:$D$861,$A9,'Manual Actuals'!$E$2:$E$861,$B9,'Manual Actuals'!$H$2:$H$861,Setup!$B$4,'Manual Actuals'!$G$2:$G$861,"Yes") | L9: =SUMIFS(bk_download!$L$2:$L$1902,bk_download!$H$2:$H$1902,$A9,bk_download!$I$2:$I$1902,$B9,bk_download!$K$2:$K$1902,Setup!$B$4,bk_download!$J$2:$J$1902,"Yes") | M9: =K9-L9
A10: Utilities | B10: Electricity | C10: =326+508+140 | D10: =IF(Setup!$B$8="Bank (Closed)",L10,K10) | E10: =C10-D10 | F10: =IF(C10=0,IF(D10=0,0,-1),(C10-D10)/C10) | G10: Medium | H10: Variable | J10: Three sources | K10: =SUMIFS('Manual Actuals'!$C$2:$C$861,'Manual Actuals'!$D$2:$D$861,$A10,'Manual Actuals'!$E$2:$E$861,$B10,'Manual Actuals'!$H$2:$H$861,Setup!$B$4,'Manual Actuals'!$G$2:$G$861,"Yes") | L10: =SUMIFS(bk_download!$L$2:$L$1902,bk_download!$H$2:$H$1902,$A10,bk_download!$I$2:$I$1902,$B10,bk_download!$K$2:$K$1902,Setup!$B$4,bk_download!$J$2:$J$1902,"Yes") | M10: =K10-L10
A11: Utilities | B11: Water/Sewer/Trash | C11: =188.88+87+100 | D11: =IF(Setup!$B$8="Bank (Closed)",L11,K11) | E11: =C11-D11 | F11: =IF(C11=0,IF(D11=0,0,-1),(C11-D11)/C11) | G11: Medium | H11: Variable | J11: Three sources | K11: =SUMIFS('Manual Actuals'!$C$2:$C$861,'Manual Actuals'!$D$2:$D$861,$A11,'Manual Actuals'!$E$2:$E$861,$B11,'Manual Actuals'!$H$2:$H$861,Setup!$B$4,'Manual Actuals'!$G$2:$G$861,"Yes") | L11: =SUMIFS(bk_download!$L$2:$L$1902,bk_download!$H$2:$H$1902,$A11,bk_download!$I$2:$I$1902,$B11,bk_download!$K$2:$K$1902,Setup!$B$4,bk_download!$J$2:$J$1902,"Yes") | M11: =K11-L11
A12: Utilities | B12: Internet | C12: 200 | D12: =IF(Setup!$B$8="Bank (Closed)",L12,K12) | E12: =C12-D12 | F12: =IF(C12=0,IF(D12=0,0,-1),(C12-D12)/C12) | G12: Medium | H12: Fixed | K12: =SUMIFS('Manual Actuals'!$C$2:$C$861,'Manual Actuals'!$D$2:$D$861,$A12,'Manual Actuals'!$E$2:$E$861,$B12,'Manual Actuals'!$H$2:$H$861,Setup!$B$4,'Manual Actuals'!$G$2:$G$861,"Yes") | L12: =SUMIFS(bk_download!$L$2:$L$1902,bk_download!$H$2:$H$1902,$A12,bk_download!$I$2:$I$1902,$B12,bk_download!$K$2:$K$1902,Setup!$B$4,bk_download!$J$2:$J$1902,"Yes") | M12: =K12-L12
A13: Utilities | B13: Telephone | C13: 500 | D13: =IF(Setup!$B$8="Bank (Closed)",L13,K13) | E13: =C13-D13 | F13: =IF(C13=0,IF(D13=0,0,-1),(C13-D13)/C13) | G13: Medium | H13: Variable | J13: Two sources | K13: =SUMIFS('Manual Actuals'!$C$2:$C$861,'Manual Actuals'!$D$2:$D$861,$A13,'Manual Actuals'!$E$2:$E$861,$B13,'Manual Actuals'!$H$2:$H$861,Setup!$B$4,'Manual Actuals'!$G$2:$G$861,"Yes") | L13: =SUMIFS(bk_download!$L$2:$L$1902,bk_download!$H$2:$H$1902,$A13,bk_download!$I$2:$I$1902,$B13,bk_download!$K$2:$K$1902,Setup!$B$4,bk_download!$J$2:$J$1902,"Yes") | M13: =K13-L13
A14: Utilities | B14: Gas | C14: 100 | D14: =IF(Setup!$B$8="Bank (Closed)",L14,K14) | E14: =C14-D14 | F14: =IF(C14=0,IF(D14=0,0,-1),(C14-D14)/C14) | G14: Medium | H14: Variable | K14: =SUMIFS('Manual Actuals'!$C$2:$C$861,'Manual Actuals'!$D$2:$D$861,$A14,'Manual Actuals'!$E$2:$E$861,$B14,'Manual Actuals'!$H$2:$H$861,Setup!$B$4,'Manual Actuals'!$G$2:$G$861,"Yes") | L14: =SUMIFS(bk_download!$L$2:$L$1902,bk_download!$H$2:$H$1902,$A14,bk_download!$I$2:$I$1902,$B14,bk_download!$K$2:$K$1902,Setup!$B$4,bk_download!$J$2:$J$1902,"Yes") | M14: =K14-L14
A15: Vehicle | B15: Car Payment | C15: =600+1459.84 | D15: =IF(Setup!$B$8="Bank (Closed)",L15,K15) | E15: =C15-D15 | F15: =IF(C15=0,IF(D15=0,0,-1),(C15-D15)/C15) | G15: Medium | H15: Fixed | J15: Two sources | K15: =SUMIFS('Manual Actuals'!$C$2:$C$861,'Manual Actuals'!$D$2:$D$861,$A15,'Manual Actuals'!$E$2:$E$861,$B15,'Manual Actuals'!$H$2:$H$861,Setup!$B$4,'Manual Actuals'!$G$2:$G$861,"Yes") | L15: =SUMIFS(bk_download!$L$2:$L$1902,bk_download!$H$2:$H$1902,$A15,bk_download!$I$2:$I$1902,$B15,bk_download!$K$2:$K$1902,Setup!$B$4,bk_download!$J$2:$J$1902,"Yes") | M15: =K15-L15
A16: Vehicle | B16: Auto Insurance | C16: =411.19+274.48+157 | D16: =IF(Setup!$B$8="Bank (Closed)",L16,K16) | E16: =C16-D16 | F16: =IF(C16=0,IF(D16=0,0,-1),(C16-D16)/C16) | G16: Medium | H16: Fixed | J16: Two sources | K16: =SUMIFS('Manual Actuals'!$C$2:$C$861,'Manual Actuals'!$D$2:$D$861,$A16,'Manual Actuals'!$E$2:$E$861,$B16,'Manual Actuals'!$H$2:$H$861,Setup!$B$4,'Manual Actuals'!$G$2:$G$861,"Yes") | L16: =SUMIFS(bk_download!$L$2:$L$1902,bk_download!$H$2:$H$1902,$A16,bk_download!$I$2:$I$1902,$B16,bk_download!$K$2:$K$1902,Setup!$B$4,bk_download!$J$2:$J$1902,"Yes") | M16: =K16-L16
A17: Vehicle | B17: Fuel | C17: 60 | D17: =IF(Setup!$B$8="Bank (Closed)",L17,K17) | E17: =C17-D17 | F17: =IF(C17=0,IF(D17=0,0,-1),(C17-D17)/C17) | G17: Medium | H17: Variable | K17: =SUMIFS('Manual Actuals'!$C$2:$C$861,'Manual Actuals'!$D$2:$D$861,$A17,'Manual Actuals'!$E$2:$E$861,$B17,'Manual Actuals'!$H$2:$H$861,Setup!$B$4,'Manual Actuals'!$G$2:$G$861,"Yes") | L17: =SUMIFS(bk_download!$L$2:$L$1902,bk_download!$H$2:$H$1902,$A17,bk_download!$I$2:$I$1902,$B17,bk_download!$K$2:$K$1902,Setup!$B$4,bk_download!$J$2:$J$1902,"Yes") | M17: =K17-L17
A18: Vehicle | B18: Maintenance/Repairs | D18: =IF(Setup!$B$8="Bank (Closed)",L18,K18) | E18: =C18-D18 | F18: =IF(C18=0,IF(D18=0,0,-1),(C18-D18)/C18) | G18: Medium | H18: Variable | K18: =SUMIFS('Manual Actuals'!$C$2:$C$861,'Manual Actuals'!$D$2:$D$861,$A18,'Manual Actuals'!$E$2:$E$861,$B18,'Manual Actuals'!$H$2:$H$861,Setup!$B$4,'Manual Actuals'!$G$2:$G$861,"Yes") | L18: =SUMIFS(bk_download!$L$2:$L$1902,bk_download!$H$2:$H$1902,$A18,bk_download!$I$2:$I$1902,$B18,bk_download!$K$2:$K$1902,Setup!$B$4,bk_download!$J$2:$J$1902,"Yes") | M18: =K18-L18
A19: Vehicle | B19: Registration/Tolls | D19: =IF(Setup!$B$8="Bank (Closed)",L19,K19) | E19: =C19-D19 | F19: =IF(C19=0,IF(D19=0,0,-1),(C19-D19)/C19) | G19: Medium | H19: Variable | K19: =SUMIFS('Manual Actuals'!$C$2:$C$861,'Manual Actuals'!$D$2:$D$861,$A19,'Manual Actuals'!$E$2:$E$861,$B19,'Manual Actuals'!$H$2:$H$861,Setup!$B$4,'Manual Actuals'!$G$2:$G$861,"Yes") | L19: =SUMIFS(bk_download!$L$2:$L$1902,bk_download!$H$2:$H$1902,$A19,bk_download!$I$2:$I$1902,$B19,bk_download!$K$2:$K$1902,Setup!$B$4,bk_download!$J$2:$J$1902,"Yes") | M19: =K19-L19
A20: Food | B20: Groceries | C20: 800 | D20: =IF(Setup!$B$8="Bank (Closed)",L20,K20) | E20: =C20-D20 | F20: =IF(C20=0,IF(D20=0,0,-1),(C20-D20)/C20) | G20: Medium | H20: Variable | K20: =SUMIFS('Manual Actuals'!$C$2:$C$861,'Manual Actuals'!$D$2:$D$861,$A20,'Manual Actuals'!$E$2:$E$861,$B20,'Manual Actuals'!$H$2:$H$861,Setup!$B$4,'Manual Actuals'!$G$2:$G$861,"Yes") | L20: =SUMIFS(bk_download!$L$2:$L$1902,bk_download!$H$2:$H$1902,$A20,bk_download!$I$2:$I$1902,$B20,bk_download!$K$2:$K$1902,Setup!$B$4,bk_download!$J$2:$J$1902,"Yes") | M20: =K20-L20
A21: Food | B21: Dining Out | C21: 500 | D21: =IF(Setup!$B$8="Bank (Closed)",L21,K21) | E21: =C21-D21 | F21: =IF(C21=0,IF(D21=0,0,-1),(C21-D21)/C21) | G21: Medium | H21: Variable | K21: =SUMIFS('Manual Actuals'!$C$2:$C$861,'Manual Actuals'!$D$2:$D$861,$A21,'Manual Actuals'!$E$2:$E$861,$B21,'Manual Actuals'!$H$2:$H$861,Setup!$B$4,'Manual Actuals'!$G$2:$G$861,"Yes") | L21: =SUMIFS(bk_download!$L$2:$L$1902,bk_download!$H$2:$H$1902,$A21,bk_download!$I$2:$I$1902,$B21,bk_download!$K$2:$K$1902,Setup!$B$4,bk_download!$J$2:$J$1902,"Yes") | M21: =K21-L21
A22: Food | B22: Household Supplies | C22: 0 | D22: =IF(Setup!$B$8="Bank (Closed)",L22,K22) | E22: =C22-D22 | F22: =IF(C22=0,IF(D22=0,0,-1),(C22-D22)/C22) | G22: Medium | H22: Variable | K22: =SUMIFS('Manual Actuals'!$C$2:$C$861,'Manual Actuals'!$D$2:$D$861,$A22,'Manual Actuals'!$E$2:$E$861,$B22,'Manual Actuals'!$H$2:$H$861,Setup!$B$4,'Manual Actuals'!$G$2:$G$861,"Yes") | L22: =SUMIFS(bk_download!$L$2:$L$1902,bk_download!$H$2:$H$1902,$A22,bk_download!$I$2:$I$1902,$B22,bk_download!$K$2:$K$1902,Setup!$B$4,bk_download!$J$2:$J$1902,"Yes") | M22: =K22-L22
A23: Insurance | B23: Life Insurance | C23: 0 | D23: =IF(Setup!$B$8="Bank (Closed)",L23,K23) | E23: =C23-D23 | F23: =IF(C23=0,IF(D23=0,0,-1),(C23-D23)/C23) | G23: Medium | H23: Variable | K23: =SUMIFS('Manual Actuals'!$C$2:$C$861,'Manual Actuals'!$D$2:$D$861,$A23,'Manual Actuals'!$E$2:$E$861,$B23,'Manual Actuals'!$H$2:$H$861,Setup!$B$4,'Manual Actuals'!$G$2:$G$861,"Yes") | L23: =SUMIFS(bk_download!$L$2:$L$1902,bk_download!$H$2:$H$1902,$A23,bk_download!$I$2:$I$1902,$B23,bk_download!$K$2:$K$1902,Setup!$B$4,bk_download!$J$2:$J$1902,"Yes") | M23: =K23-L23
A24: Insurance | B24: Disability/Other | C24: 0 | D24: =IF(Setup!$B$8="Bank (Closed)",L24,K24) | E24: =C24-D24 | F24: =IF(C24=0,IF(D24=0,0,-1),(C24-D24)/C24) | G24: Medium | H24: Variable | K24: =SUMIFS('Manual Actuals'!$C$2:$C$861,'Manual Actuals'!$D$2:$D$861,$A24,'Manual Actuals'!$E$2:$E$861,$B24,'Manual Actuals'!$H$2:$H$861,Setup!$B$4,'Manual Actuals'!$G$2:$G$861,"Yes") | L24: =SUMIFS(bk_download!$L$2:$L$1902,bk_download!$H$2:$H$1902,$A24,bk_download!$I$2:$I$1902,$B24,bk_download!$K$2:$K$1902,Setup!$B$4,bk_download!$J$2:$J$1902,"Yes") | M24: =K24-L24
A25: Medical | B25: Healthcare | C25: 0 | D25: =IF(Setup!$B$8="Bank (Closed)",L25,K25) | E25: =C25-D25 | F25: =IF(C25=0,IF(D25=0,0,-1),(C25-D25)/C25) | G25: Medium | H25: Variable | J25: DV Benefit | K25: =SUMIFS('Manual Actuals'!$C$2:$C$861,'Manual Actuals'!$D$2:$D$861,$A25,'Manual Actuals'!$E$2:$E$861,$B25,'Manual Actuals'!$H$2:$H$861,Setup!$B$4,'Manual Actuals'!$G$2:$G$861,"Yes") | L25: =SUMIFS(bk_download!$L$2:$L$1902,bk_download!$H$2:$H$1902,$A25,bk_download!$I$2:$I$1902,$B25,bk_download!$K$2:$K$1902,Setup!$B$4,bk_download!$J$2:$J$1902,"Yes") | M25: =K25-L25
A26: Medical | B26: Prescriptions | C26: 0 | D26: =IF(Setup!$B$8="Bank (Closed)",L26,K26) | E26: =C26-D26 | F26: =IF(C26=0,IF(D26=0,0,-1),(C26-D26)/C26) | G26: Medium | H26: Variable | J26: DV Benefit | K26: =SUMIFS('Manual Actuals'!$C$2:$C$861,'Manual Actuals'!$D$2:$D$861,$A26,'Manual Actuals'!$E$2:$E$861,$B26,'Manual Actuals'!$H$2:$H$861,Setup!$B$4,'Manual Actuals'!$G$2:$G$861,"Yes") | L26: =SUMIFS(bk_download!$L$2:$L$1902,bk_download!$H$2:$H$1902,$A26,bk_download!$I$2:$I$1902,$B26,bk_download!$K$2:$K$1902,Setup!$B$4,bk_download!$J$2:$J$1902,"Yes") | M26: =K26-L26
A27: Medical | B27: Dental/Vision | C27: =40.76+12.31 | D27: =IF(Setup!$B$8="Bank (Closed)",L27,K27) | E27: =C27-D27 | F27: =IF(C27=0,IF(D27=0,0,-1),(C27-D27)/C27) | G27: Medium | H27: Fixed | J27: Dental and Vision for just one source | K27: =SUMIFS('Manual Actuals'!$C$2:$C$861,'Manual Actuals'!$D$2:$D$861,$A27,'Manual Actuals'!$E$2:$E$861,$B27,'Manual Actuals'!$H$2:$H$861,Setup!$B$4,'Manual Actuals'!$G$2:$G$861,"Yes") | L27: =SUMIFS(bk_download!$L$2:$L$1902,bk_download!$H$2:$H$1902,$A27,bk_download!$I$2:$I$1902,$B27,bk_download!$K$2:$K$1902,Setup!$B$4,bk_download!$J$2:$J$1902,"Yes") | M27: =K27-L27
A28: Children | B28: Child/Dependent | C28: 0 | D28: =IF(Setup!$B$8="Bank (Closed)",L28,K28) | E28: =C28-D28 | F28: =IF(C28=0,IF(D28=0,0,-1),(C28-D28)/C28) | G28: Medium | H28: Variable | K28: =SUMIFS('Manual Actuals'!$C$2:$C$861,'Manual Actuals'!$D$2:$D$861,$A28,'Manual Actuals'!$E$2:$E$861,$B28,'Manual Actuals'!$H$2:$H$861,Setup!$B$4,'Manual Actuals'!$G$2:$G$861,"Yes") | L28: =SUMIFS(bk_download!$L$2:$L$1902,bk_download!$H$2:$H$1902,$A28,bk_download!$I$2:$I$1902,$B28,bk_download!$K$2:$K$1902,Setup!$B$4,bk_download!$J$2:$J$1902,"Yes") | M28: =K28-L28
A29: Children | B29: School/Activities | C29: 0 | D29: =IF(Setup!$B$8="Bank (Closed)",L29,K29) | E29: =C29-D29 | F29: =IF(C29=0,IF(D29=0,0,-1),(C29-D29)/C29) | G29: Medium | H29: Variable | K29: =SUMIFS('Manual Actuals'!$C$2:$C$861,'Manual Actuals'!$D$2:$D$861,$A29,'Manual Actuals'!$E$2:$E$861,$B29,'Manual Actuals'!$H$2:$H$861,Setup!$B$4,'Manual Actuals'!$G$2:$G$861,"Yes") | L29: =SUMIFS(bk_download!$L$2:$L$1902,bk_download!$H$2:$H$1902,$A29,bk_download!$I$2:$I$1902,$B29,bk_download!$K$2:$K$1902,Setup!$B$4,bk_download!$J$2:$J$1902,"Yes") | M29: =K29-L29
A30: Personal Care | B30: Personal Care | C30: 120 | D30: =IF(Setup!$B$8="Bank (Closed)",L30,K30) | E30: =C30-D30 | F30: =IF(C30=0,IF(D30=0,0,-1),(C30-D30)/C30) | G30: Medium | H30: Variable | J30: Two sources | K30: =SUMIFS('Manual Actuals'!$C$2:$C$861,'Manual Actuals'!$D$2:$D$861,$A30,'Manual Actuals'!$E$2:$E$861,$B30,'Manual Actuals'!$H$2:$H$861,Setup!$B$4,'Manual Actuals'!$G$2:$G$861,"Yes") | L30: =SUMIFS(bk_download!$L$2:$L$1902,bk_download!$H$2:$H$1902,$A30,bk_download!$I$2:$I$1902,$B30,bk_download!$K$2:$K$1902,Setup!$B$4,bk_download!$J$2:$J$1902,"Yes") | M30: =K30-L30
A31: Personal Care | B31: Clothing | C31: 0 | D31: =IF(Setup!$B$8="Bank (Closed)",L31,K31) | E31: =C31-D31 | F31: =IF(C31=0,IF(D31=0,0,-1),(C31-D31)/C31) | G31: Medium | H31: Variable | K31: =SUMIFS('Manual Actuals'!$C$2:$C$861,'Manual Actuals'!$D$2:$D$861,$A31,'Manual Actuals'!$E$2:$E$861,$B31,'Manual Actuals'!$H$2:$H$861,Setup!$B$4,'Manual Actuals'!$G$2:$G$861,"Yes") | L31: =SUMIFS(bk_download!$L$2:$L$1902,bk_download!$H$2:$H$1902,$A31,bk_download!$I$2:$I$1902,$B31,bk_download!$K$2:$K$1902,Setup!$B$4,bk_download!$J$2:$J$1902,"Yes") | M31: =K31-L31
A32: Personal Care | B32: Hair/Nails | C32: 350 | D32: =IF(Setup!$B$8="Bank (Closed)",L32,K32) | E32: =C32-D32 | F32: =IF(C32=0,IF(D32=0,0,-1),(C32-D32)/C32) | G32: Medium | H32: Variable | J32: Two sources | K32: =SUMIFS('Manual Actuals'!$C$2:$C$861,'Manual Actuals'!$D$2:$D$861,$A32,'Manual Actuals'!$E$2:$E$861,$B32,'Manual Actuals'!$H$2:$H$861,Setup!$B$4,'Manual Actuals'!$G$2:$G$861,"Yes") | L32: =SUMIFS(bk_download!$L$2:$L$1902,bk_download!$H$2:$H$1902,$A32,bk_download!$I$2:$I$1902,$B32,bk_download!$K$2:$K$1902,Setup!$B$4,bk_download!$J$2:$J$1902,"Yes") | M32: =K32-L32
A33: Entertainment | B33: Entertainment | C33: 400 | D33: =IF(Setup!$B$8="Bank (Closed)",L33,K33) | E33: =C33-D33 | F33: =IF(C33=0,IF(D33=0,0,-1),(C33-D33)/C33) | G33: Medium | H33: Variable | K33: =SUMIFS('Manual Actuals'!$C$2:$C$861,'Manual Actuals'!$D$2:$D$861,$A33,'Manual Actuals'!$E$2:$E$861,$B33,'Manual Actuals'!$H$2:$H$861,Setup!$B$4,'Manual Actuals'!$G$2:$G$861,"Yes") | L33: =SUMIFS(bk_download!$L$2:$L$1902,bk_download!$H$2:$H$1902,$A33,bk_download!$I$2:$I$1902,$B33,bk_download!$K$2:$K$1902,Setup!$B$4,bk_download!$J$2:$J$1902,"Yes") | M33: =K33-L33
A34: Entertainment | B34: Online Services | C34: 300 | D34: =IF(Setup!$B$8="Bank (Closed)",L34,K34) | E34: =C34-D34 | F34: =IF(C34=0,IF(D34=0,0,-1),(C34-D34)/C34) | G34: Medium | H34: Variable | K34: =SUMIFS('Manual Actuals'!$C$2:$C$861,'Manual Actuals'!$D$2:$D$861,$A34,'Manual Actuals'!$E$2:$E$861,$B34,'Manual Actuals'!$H$2:$H$861,Setup!$B$4,'Manual Actuals'!$G$2:$G$861,"Yes") | L34: =SUMIFS(bk_download!$L$2:$L$1902,bk_download!$H$2:$H$1902,$A34,bk_download!$I$2:$I$1902,$B34,bk_download!$K$2:$K$1902,Setup!$B$4,bk_download!$J$2:$J$1902,"Yes") | M34: =K34-L34
A35: Entertainment | B35: Subscriptions | C35: 300 | D35: =IF(Setup!$B$8="Bank (Closed)",L35,K35) | E35: =C35-D35 | F35: =IF(C35=0,IF(D35=0,0,-1),(C35-D35)/C35) | G35: Medium | H35: Variable | K35: =SUMIFS('Manual Actuals'!$C$2:$C$861,'Manual Actuals'!$D$2:$D$861,$A35,'Manual Actuals'!$E$2:$E$861,$B35,'Manual Actuals'!$H$2:$H$861,Setup!$B$4,'Manual Actuals'!$G$2:$G$861,"Yes") | L35: =SUMIFS(bk_download!$L$2:$L$1902,bk_download!$H$2:$H$1902,$A35,bk_download!$I$2:$I$1902,$B35,bk_download!$K$2:$K$1902,Setup!$B$4,bk_download!$J$2:$J$1902,"Yes") | M35: =K35-L35
A36: Subscriptions | B36: Streaming | C36: 400 | D36: =IF(Setup!$B$8="Bank (Closed)",L36,K36) | E36: =C36-D36 | F36: =IF(C36=0,IF(D36=0,0,-1),(C36-D36)/C36) | G36: Medium | H36: Fixed | K36: =SUMIFS('Manual Actuals'!$C$2:$C$861,'Manual Actuals'!$D$2:$D$861,$A36,'Manual Actuals'!$E$2:$E$861,$B36,'Manual Actuals'!$H$2:$H$861,Setup!$B$4,'Manual Actuals'!$G$2:$G$861,"Yes") | L36: =SUMIFS(bk_download!$L$2:$L$1902,bk_download!$H$2:$H$1902,$A36,bk_download!$I$2:$I$1902,$B36,bk_download!$K$2:$K$1902,Setup!$B$4,bk_download!$J$2:$J$1902,"Yes") | M36: =K36-L36
A37: Subscriptions | B37: Music | C37: 200 | D37: =IF(Setup!$B$8="Bank (Closed)",L37,K37) | E37: =C37-D37 | F37: =IF(C37=0,IF(D37=0,0,-1),(C37-D37)/C37) | G37: Medium | H37: Fixed | K37: =SUMIFS('Manual Actuals'!$C$2:$C$861,'Manual Actuals'!$D$2:$D$861,$A37,'Manual Actuals'!$E$2:$E$861,$B37,'Manual Actuals'!$H$2:$H$861,Setup!$B$4,'Manual Actuals'!$G$2:$G$861,"Yes") | L37: =SUMIFS(bk_download!$L$2:$L$1902,bk_download!$H$2:$H$1902,$A37,bk_download!$I$2:$I$1902,$B37,bk_download!$K$2:$K$1902,Setup!$B$4,bk_download!$J$2:$J$1902,"Yes") | M37: =K37-L37
A38: Subscriptions | B38: Software/Apps | C38: 500 | D38: =IF(Setup!$B$8="Bank (Closed)",L38,K38) | E38: =C38-D38 | F38: =IF(C38=0,IF(D38=0,0,-1),(C38-D38)/C38) | G38: Medium | H38: Fixed | K38: =SUMIFS('Manual Actuals'!$C$2:$C$861,'Manual Actuals'!$D$2:$D$861,$A38,'Manual Actuals'!$E$2:$E$861,$B38,'Manual Actuals'!$H$2:$H$861,Setup!$B$4,'Manual Actuals'!$G$2:$G$861,"Yes") | L38: =SUMIFS(bk_download!$L$2:$L$1902,bk_download!$H$2:$H$1902,$A38,bk_download!$I$2:$I$1902,$B38,bk_download!$K$2:$K$1902,Setup!$B$4,bk_download!$J$2:$J$1902,"Yes") | M38: =K38-L38
A39: Subscriptions | B39: Other Subscriptions | C39: 500 | D39: =IF(Setup!$B$8="Bank (Closed)",L39,K39) | E39: =C39-D39 | F39: =IF(C39=0,IF(D39=0,0,-1),(C39-D39)/C39) | G39: Medium | H39: Fixed | K39: =SUMIFS('Manual Actuals'!$C$2:$C$861,'Manual Actuals'!$D$2:$D$861,$A39,'Manual Actuals'!$E$2:$E$861,$B39,'Manual Actuals'!$H$2:$H$861,Setup!$B$4,'Manual Actuals'!$G$2:$G$861,"Yes") | L39: =SUMIFS(bk_download!$L$2:$L$1902,bk_download!$H$2:$H$1902,$A39,bk_download!$I$2:$I$1902,$B39,bk_download!$K$2:$K$1902,Setup!$B$4,bk_download!$J$2:$J$1902,"Yes") | M39: =K39-L39
A40: Giving | B40: Tithe/Charity | C40: 0 | D40: =IF(Setup!$B$8="Bank (Closed)",L40,K40) | E40: =C40-D40 | F40: =IF(C40=0,IF(D40=0,0,-1),(C40-D40)/C40) | G40: Medium | H40: Variable | K40: =SUMIFS('Manual Actuals'!$C$2:$C$861,'Manual Actuals'!$D$2:$D$861,$A40,'Manual Actuals'!$E$2:$E$861,$B40,'Manual Actuals'!$H$2:$H$861,Setup!$B$4,'Manual Actuals'!$G$2:$G$861,"Yes") | L40: =SUMIFS(bk_download!$L$2:$L$1902,bk_download!$H$2:$H$1902,$A40,bk_download!$I$2:$I$1902,$B40,bk_download!$K$2:$K$1902,Setup!$B$4,bk_download!$J$2:$J$1902,"Yes") | M40: =K40-L40
A41: Giving | B41: Gifts | C41: 0 | D41: =IF(Setup!$B$8="Bank (Closed)",L41,K41) | E41: =C41-D41 | F41: =IF(C41=0,IF(D41=0,0,-1),(C41-D41)/C41) | G41: Medium | H41: Variable | K41: =SUMIFS('Manual Actuals'!$C$2:$C$861,'Manual Actuals'!$D$2:$D$861,$A41,'Manual Actuals'!$E$2:$E$861,$B41,'Manual Actuals'!$H$2:$H$861,Setup!$B$4,'Manual Actuals'!$G$2:$G$861,"Yes") | L41: =SUMIFS(bk_download!$L$2:$L$1902,bk_download!$H$2:$H$1902,$A41,bk_download!$I$2:$I$1902,$B41,bk_download!$K$2:$K$1902,Setup!$B$4,bk_download!$J$2:$J$1902,"Yes") | M41: =K41-L41
...

Sheet Manual Actuals
A1: Date | B1: Description | C1: Actual Amount ($) | D1: Budget Category | E1: Subcategory | F1: Account | G1: Include? | H1: Month | I1: Notes
A2: 46232 | B2: City of Killeen | C2: 121 | D2: Utilities | E2: Water/Sewer/Trash | F2: Checking | G2: Yes | H2: August 2026
A3: 46233 | B3: Google YouTube | C3: 82.89 | D3: Subscriptions | E3: Streaming | F3: Checking | G3: Yes | H3: August 2026
A4: 46232 | B4: Camden Food Gates | C4: 16.5 | D4: Food | E4: Dining Out | F4: Checking | G4: Yes | H4: August 2026
A5: 46232 | B5: Dunkin donuts | C5: 3.97 | D5: Food | E5: Dining Out | F5: Checking | G5: Yes | H5: August 2026
A6: 46231 | B6: YouTube TV | C6: 29.99 | D6: Subscriptions | E6: Streaming | F6: Checking | G6: Yes | H6: July 2026
A7: 46232 | B7: Star Mart | C7: 30 | D7: Vehicle | E7: Fuel | F7: Checking | G7: Yes | H7: August 2026
A8: 46232 | B8: Amazon Delivery | C8: 75.04 | D8: Subscriptions | E8: Other Subscriptions | F8: Checking | G8: Yes | H8: August 2026
A9: 46233 | B9: BOA Home Loan | C9: 406.91 | D9: Housing | E9: Mortgage/Rent | F9: Checking | G9: Yes | H9: August 2026
A10: 46232 | B10: American home Shield | C10: 138.99 | D10: Housing | E10: Home Insurance | F10: Checking | G10: Yes | H10: August 2026
A11: 46232 | B11: Star Mart | C11: 202.95 | D11: Miscellaneous | E11: Cash/ATM | F11: Checking | G11: Yes | H11: August 2026
A12: 46233 | B12: Tommy Express | C12: 50.98 | D12: Subscriptions | E12: Other Subscriptions | F12: Checking | G12: Yes | H12: August 2026
A13: 46233 | B13: Google YouTube premium | C13: 29.22 | D13: Subscriptions | E13: Streaming | F13: Checking | G13: Yes | H13: August 2026
... A20: 46233 | B20: Affirm | C20: 22.31 | D20: Debt | E20: Loans | F20: Checking | G20: Yes | H20: August 2026
A21: 46241 | B21: T-Mobile | C21: 154.67 | D21: Utilities | E21: Telephone | F21: Checking | G21: Yes | H21: August 2026 | I21: Imported from bank
A22: 46239 | B22: Just Energy | C22: 362.14 | D22: Utilities | E22: Electricity | F22: Checking | G22: Yes | H22: August 2026 | I22: Imported from bank
A23: 46239 | B23: Just Energy | C23: 38.03 | D23: Utilities | E23: Electricity | F23: Checking | G23: Yes | H23: August 2026 | I23: Imported from bank
A24: 46239 | B24: H-E-B | C24: 135.25 | D24: Food | E24: Groceries | F24: Checking | G24: Yes | H24: August 2026 | I24: Imported from bank
A25: 46239 | B25: Jamaica Nyammingz | C25: 41.59 | D25: Food | E25: Dining Out | F25: Checking | G25: Yes | H25: August 2026 | I25: Imported from bank
A26: 46238 | B26: McDonald's | C26: 14.16 | D26: Food | E26: Dining Out | F26: Checking | G26: Yes | H26: August 2026 | I26: Imported from bank
A27: 46237 | B27: H-E-B | C27: 114.89 | D27: Food | E27: Groceries | F27: Checking | G27: Yes | H27: August 2026 | I27: Imported from bank
A28: 46237 | B28: Pluckers | C28: 99.07 | D28: Food | E28: Dining Out | F28: Checking | G28: Yes | H28: August 2026 | I28: Imported from bank
A29: 46237 | B29: The Point Liquor | C29: 35.71 | D29: Food | E29: Dining Out | F29: Checking | G29: Yes | H29: August 2026 | I29: Imported from bank
A30: 46237 | B30: Regal | C30: 25.41 | D30: Entertainment | E30: Entertainment | F30: Checking | G30: Yes | H30: August 2026 | I30: Imported from bank
A31: 46237 | B31: Casey's | C31: 12.81 | D31: Vehicle | E31: Fuel | F31: Checking | G31: Yes | H31: August 2026 | I31: Imported from bank
A32: 46237 | B32: Chill Zone | C32: 11.64 | D32: Miscellaneous | E32: General Merchandise | F32: Checking | G32: Yes | H32: August 2026 | I32: Imported from bank
... A45: 46230 | B45: City of Orlando | C45: 10 | D45: Utilities | E45: Electricity | F45: Checking | G45: Yes | H45: July 2026 | I45: Imported from bank
H46: =IF(A46="","",TEXT(IF(DAY(A46)>=Setup!$B$9,DATE(YEAR(A46),MONTH(A46)+1,1),DATE(YEAR(A46),MONTH(A46),1)),"mmmm yyyy"))
H47: =IF(A47="","",TEXT(IF(DAY(A47)>=Setup!$B$9,DATE(YEAR(A47),MONTH(A47)+1,1),DATE(YEAR(A47),MONTH(A47),1)),"mmmm yyyy"))
H48: =IF(A48="","",TEXT(IF(DAY(A48)>=Setup!$B$9,DATE(YEAR(A48),MONTH(A48)+1,1),DATE(YEAR(A48),MONTH(A48),1)),"mmmm yyyy"))
H49: =IF(A49="","",TEXT(IF(DAY(A49)>=Setup!$B$9,DATE(YEAR(A49),MONTH(A49)+1,1),DATE(YEAR(A49),MONTH(A49),1)),"mmmm yyyy"))
H50: =IF(A50="","",TEXT(IF(DAY(A50)>=Setup!$B$9,DATE(YEAR(A50),MONTH(A50)+1,1),DATE(YEAR(A50),MONTH(A50),1)),"mmmm yyyy"))
H51: =IF(A51="","",TEXT(IF(DAY(A51)>=Setup!$B$9,DATE(YEAR(A51),MONTH(A51)+1,1),DATE(YEAR(A51),MONTH(A51),1)),"mmmm yyyy"))
H52: =IF(A52="","",TEXT(IF(DAY(A52)>=Setup!$B$9,DATE(YEAR(A52),MONTH(A52)+1,1),DATE(YEAR(A52),MONTH(A52),1)),"mmmm yyyy"))
H53: =IF(A53="","",TEXT(IF(DAY(A53)>=Setup!$B$9,DATE(YEAR(A53),MONTH(A53)+1,1),DATE(YEAR(A53),MONTH(A53),1)),"mmmm yyyy"))
H54: =IF(A54="","",TEXT(IF(DAY(A54)>=Setup!$B$9,DATE(YEAR(A54),MONTH(A54)+1,1),DATE(YEAR(A54),MONTH(A54),1)),"mmmm yyyy"))
H55: =IF(A55="","",TEXT(IF(DAY(A55)>=Setup!$B$9,DATE(YEAR(A55),MONTH(A55)+1,1),DATE(YEAR(A55),MONTH(A55),1)),"mmmm yyyy"))
H56: =IF(A56="","",TEXT(IF(DAY(A56)>=Setup!$B$9,DATE(YEAR(A56),MONTH(A56)+1,1),DATE(YEAR(A56),MONTH(A56),1)),"mmmm yyyy"))
H57: =IF(A57="","",TEXT(IF(DAY(A57)>=Setup!$B$9,DATE(YEAR(A57),MONTH(A57)+1,1),DATE(YEAR(A57),MONTH(A57),1)),"mmmm yyyy"))
... H861: =IF(A861="","",TEXT(IF(DAY(A861)>=Setup!$B$9,DATE(YEAR(A861),MONTH(A861)+1,1),DATE(YEAR(A861),MONTH(A861),1)),"mmmm yyyy"))

Sheet Monthly Summary
A1: MONTHLY CATEGORY SUMMARY
A3: Category | B3: Planned ($) | C3: Actual ($) | D3: Remaining ($) | E3: Variance % | F3: Share of Spend | G3: Status | H3: Trend Note
A4: Housing | B4: =SUMIF('Budget Plan'!$A$4:$A$55,A4,'Budget Plan'!$C$4:$C$55) | C4: =SUMIF('Budget Plan'!$A$4:$A$55,A4,'Budget Plan'!$D$4:$D$55) | D4: =B4-C4 | E4: =IF(B4=0,IF(C4=0,0,-1),D4/B4) | F4: =IF(SUM($C$4:$C$20)=0,0,C4/SUM($C$4:$C$20)) | G4: =IF(C4=0,"No Activity",IF(D4<0,"Over Budget",IF(C4>B4*0.9,"Watch","On Track"))) | H4: =IF(C4=0,"No bank expenses imported",IF(D4<0,"Reduce or reallocate "&TEXT(-D4,"$#,##0"),"Available "&TEXT(D4,"$#,##0")))
A5: Utilities | B5: =SUMIF('Budget Plan'!$A$4:$A$55,A5,'Budget Plan'!$C$4:$C$55) | C5: =SUMIF('Budget Plan'!$A$4:$A$55,A5,'Budget Plan'!$D$4:$D$55) | D5: =B5-C5 | E5: =IF(B5=0,IF(C5=0,0,-1),D5/B5) | F5: =IF(SUM($C$4:$C$20)=0,0,C5/SUM($C$4:$C$20)) | G5: =IF(C5=0,"No Activity",IF(D5<0,"Over Budget",IF(C5>B5*0.9,"Watch","On Track"))) | H5: =IF(C5=0,"No bank expenses imported",IF(D5<0,"Reduce or reallocate "&TEXT(-D5,"$#,##0"),"Available "&TEXT(D5,"$#,##0")))
A6: Vehicle | B6: =SUMIF('Budget Plan'!$A$4:$A$55,A6,'Budget Plan'!$C$4:$C$55) | C6: =SUMIF('Budget Plan'!$A$4:$A$55,A6,'Budget Plan'!$D$4:$D$55) | D6: =B6-C6 | E6: =IF(B6=0,IF(C6=0,0,-1),D6/B6) | F6: =IF(SUM($C$4:$C$20)=0,0,C6/SUM($C$4:$C$20)) | G6: =IF(C6=0,"No Activity",IF(D6<0,"Over Budget",IF(C6>B6*0.9,"Watch","On Track"))) | H6: =IF(C6=0,"No bank expenses imported",IF(D6<0,"Reduce or reallocate "&TEXT(-D6,"$#,##0"),"Available "&TEXT(D6,"$#,##0")))
A7: Food | B7: =SUMIF('Budget Plan'!$A$4:$A$55,A7,'Budget Plan'!$C$4:$C$55) | C7: =SUMIF('Budget Plan'!$A$4:$A$55,A7,'Budget Plan'!$D$4:$D$55) | D7: =B7-C7 | E7: =IF(B7=0,IF(C7=0,0,-1),D7/B7) | F7: =IF(SUM($C$4:$C$20)=0,0,C7/SUM($C$4:$C$20)) | G7: =IF(C7=0,"No Activity",IF(D7<0,"Over Budget",IF(C7>B7*0.9,"Watch","On Track"))) | H7: =IF(C7=0,"No bank expenses imported",IF(D7<0,"Reduce or reallocate "&TEXT(-D7,"$#,##0"),"Available "&TEXT(D7,"$#,##0")))
A8: Insurance | B8: =SUMIF('Budget Plan'!$A$4:$A$55,A8,'Budget Plan'!$C$4:$C$55) | C8: =SUMIF('Budget Plan'!$A$4:$A$55,A8,'Budget Plan'!$D$4:$D$55) | D8: =B8-C8 | E8: =IF(B8=0,IF(C8=0,0,-1),D8/B8) | F8: =IF(SUM($C$4:$C$20)=0,0,C8/SUM($C$4:$C$20)) | G8: =IF(C8=0,"No Activity",IF(D8<0,"Over Budget",IF(C8>B8*0.9,"Watch","On Track"))) | H8: =IF(C8=0,"No bank expenses imported",IF(D8<0,"Reduce or reallocate "&TEXT(-D8,"$#,##0"),"Available "&TEXT(D8,"$#,##0")))
A9: Medical | B9: =SUMIF('Budget Plan'!$A$4:$A$55,A9,'Budget Plan'!$C$4:$C$55) | C9: =SUMIF('Budget Plan'!$A$4:$A$55,A9,'Budget Plan'!$D$4:$D$55) | D9: =B9-C9 | E9: =IF(B9=0,IF(C9=0,0,-1),D9/B9) | F9: =IF(SUM($C$4:$C$20)=0,0,C9/SUM($C$4:$C$20)) | G9: =IF(C9=0,"No Activity",IF(D9<0,"Over Budget",IF(C9>B9*0.9,"Watch","On Track"))) | H9: =IF(C9=0,"No bank expenses imported",IF(D9<0,"Reduce or reallocate "&TEXT(-D9,"$#,##0"),"Available "&TEXT(D9,"$#,##0")))
A10: Children | B10: =SUMIF('Budget Plan'!$A$4:$A$55,A10,'Budget Plan'!$C$4:$C$55) | C10: =SUMIF('Budget Plan'!$A$4:$A$55,A10,'Budget Plan'!$D$4:$D$55) | D10: =B10-C10 | E10: =IF(B10=0,IF(C10=0,0,-1),D10/B10) | F10: =IF(SUM($C$4:$C$20)=0,0,C10/SUM($C$4:$C$20)) | G10: =IF(C10=0,"No Activity",IF(D10<0,"Over Budget",IF(C10>B10*0.9,"Watch","On Track"))) | H10: =IF(C10=0,"No bank expenses imported",IF(D10<0,"Reduce or reallocate "&TEXT(-D10,"$#,##0"),"Available "&TEXT(D10,"$#,##0")))
A11: Personal Care | B11: =SUMIF('Budget Plan'!$A$4:$A$55,A11,'Budget Plan'!$C$4:$C$55) | C11: =SUMIF('Budget Plan'!$A$4:$A$55,A11,'Budget Plan'!$D$4:$D$55) | D11: =B11-C11 | E11: =IF(B11=0,IF(C11=0,0,-1),D11/B11) | F11: =IF(SUM($C$4:$C$20)=0,0,C11/SUM($C$4:$C$20)) | G11: =IF(C11=0,"No Activity",IF(D11<0,"Over Budget",IF(C11>B11*0.9,"Watch","On Track"))) | H11: =IF(C11=0,"No bank expenses imported",IF(D11<0,"Reduce or reallocate "&TEXT(-D11,"$#,##0"),"Available "&TEXT(D11,"$#,##0")))
A12: Entertainment | B12: =SUMIF('Budget Plan'!$A$4:$A$55,A12,'Budget Plan'!$C$4:$C$55) | C12: =SUMIF('Budget Plan'!$A$4:$A$55,A12,'Budget Plan'!$D$4:$D$55) | D12: =B12-C12 | E12: =IF(B12=0,IF(C12=0,0,-1),D12/B12) | F12: =IF(SUM($C$4:$C$20)=0,0,C12/SUM($C$4:$C$20)) | G12: =IF(C12=0,"No Activity",IF(D12<0,"Over Budget",IF(C12>B12*0.9,"Watch","On Track"))) | H12: =IF(C12=0,"No bank expenses imported",IF(D12<0,"Reduce or reallocate "&TEXT(-D12,"$#,##0"),"Available "&TEXT(D12,"$#,##0")))
A13: Subscriptions | B13: =SUMIF('Budget Plan'!$A$4:$A$60,"Subscriptions",'Budget Plan'!$C$4:$C$60) | C13: =SUMIF('Budget Plan'!$A$4:$A$60,"Subscriptions",'Budget Plan'!$D$4:$D$60) | D13: =B13-C13 | E13: =IF(B13=0,IF(C13=0,0,-1),(B13-C13)/B13) | F13: =IF($C$20=0,0,C13/$C$20) | G13: =IF(C13=0,"No Activity",IF(E13>=0.1,"On Track",IF(E13>=0,"Close","Over Budget"))) | H13: =IF(C13=0,"No bank expenses imported","Available "&TEXT(D13,"$#,##0"))
A14: Giving | B14: =SUMIF('Budget Plan'!$A$4:$A$55,A14,'Budget Plan'!$C$4:$C$55) | C14: =SUMIF('Budget Plan'!$A$4:$A$55,A14,'Budget Plan'!$D$4:$D$55) | D14: =B14-C14 | E14: =IF(B14=0,IF(C14=0,0,-1),D14/B14) | F14: =IF(SUM($C$4:$C$20)=0,0,C14/SUM($C$4:$C$20)) | G14: =IF(C14=0,"No Activity",IF(D14<0,"Over Budget",IF(C14>B14*0.9,"Watch","On Track"))) | H14: =IF(C14=0,"No bank expenses imported",IF(D14<0,"Reduce or reallocate "&TEXT(-D14,"$#,##0"),"Available "&TEXT(D14,"$#,##0")))
A15: Pets | B15: =SUMIF('Budget Plan'!$A$4:$A$55,A15,'Budget Plan'!$C$4:$C$55) | C15: =SUMIF('Budget Plan'!$A$4:$A$55,A15,'Budget Plan'!$D$4:$D$55) | D15: =B15-C15 | E15: =IF(B15=0,IF(C15=0,0,-1),D15/B15) | F15: =IF(SUM($C$4:$C$20)=0,0,C15/SUM($C$4:$C$20)) | G15: =IF(C15=0,"No Activity",IF(D15<0,"Over Budget",IF(C15>B15*0.9,"Watch","On Track"))) | H15: =IF(C15=0,"No bank expenses imported",IF(D15<0,"Reduce or reallocate "&TEXT(-D15,"$#,##0"),"Available "&TEXT(D15,"$#,##0")))
A16: Debt | B16: =SUMIF('Budget Plan'!$A$4:$A$55,A16,'Budget Plan'!$C$4:$C$55) | C16: =SUMIF('Budget Plan'!$A$4:$A$55,A16,'Budget Plan'!$D$4:$D$55) | D16: =B16-C16 | E16: =IF(B16=0,IF(C16=0,0,-1),D16/B16) | F16: =IF(SUM($C$4:$C$20)=0,0,C16/SUM($C$4:$C$20)) | G16: =IF(C16=0,"No Activity",IF(D16<0,"Over Budget",IF(C16>B16*0.9,"Watch","On Track"))) | H16: =IF(C16=0,"No bank expenses imported",IF(D16<0,"Reduce or reallocate "&TEXT(-D16,"$#,##0"),"Available "&TEXT(D16,"$#,##0")))
A17: Savings | B17: =SUMIF('Budget Plan'!$A$4:$A$55,A17,'Budget Plan'!$C$4:$C$55) | C17: =SUMIF('Budget Plan'!$A$4:$A$55,A17,'Budget Plan'!$D$4:$D$55) | D17: =B17-C17 | E17: =IF(B17=0,IF(C17=0,0,-1),D17/B17) | F17: =IF(SUM($C$4:$C$20)=0,0,C17/SUM($C$4:$C$20)) | G17: =IF(C17=0,"No Activity",IF(D17<0,"Over Budget",IF(C17>B17*0.9,"Watch","On Track"))) | H17: =IF(C17=0,"No bank expenses imported",IF(D17<0,"Reduce or reallocate "&TEXT(-D17,"$#,##0"),"Available "&TEXT(D17,"$#,##0")))
A18: Taxes | B18: =SUMIF('Budget Plan'!$A$4:$A$55,A18,'Budget Plan'!$C$4:$C$55) | C18: =SUMIF('Budget Plan'!$A$4:$A$55,A18,'Budget Plan'!$D$4:$D$55) | D18: =B18-C18 | E18: =IF(B18=0,IF(C18=0,0,-1),D18/B18) | F18: =IF(SUM($C$4:$C$20)=0,0,C18/SUM($C$4:$C$20)) | G18: =IF(C18=0,"No Activity",IF(D18<0,"Over Budget",IF(C18>B18*0.9,"Watch","On Track"))) | H18: =IF(C18=0,"No bank expenses imported",IF(D18<0,"Reduce or reallocate "&TEXT(-D18,"$#,##0"),"Available "&TEXT(D18,"$#,##0")))
A19: Legal | B19: =SUMIF('Budget Plan'!$A$4:$A$55,A19,'Budget Plan'!$C$4:$C$55) | C19: =SUMIF('Budget Plan'!$A$4:$A$55,A19,'Budget Plan'!$D$4:$D$55) | D19: =B19-C19 | E19: =IF(B19=0,IF(C19=0,0,-1),D19/B19) | F19: =IF(SUM($C$4:$C$20)=0,0,C19/SUM($C$4:$C$20)) | G19: =IF(C19=0,"No Activity",IF(D19<0,"Over Budget",IF(C19>B19*0.9,"Watch","On Track"))) | H19: =IF(C19=0,"No bank expenses imported",IF(D19<0,"Reduce or reallocate "&TEXT(-D19,"$#,##0"),"Available "&TEXT(D19,"$#,##0")))
A20: Miscellaneous | B20: =SUMIF('Budget Plan'!$A$4:$A$55,A20,'Budget Plan'!$C$4:$C$55) | C20: =SUMIF('Budget Plan'!$A$4:$A$55,A20,'Budget Plan'!$D$4:$D$55) | D20: =B20-C20 | E20: =IF(B20=0,IF(C20=0,0,-1),D20/B20) | F20: =IF(SUM($C$4:$C$20)=0,0,C20/SUM($C$4:$C$20)) | G20: =IF(C20=0,"No Activity",IF(D20<0,"Over Budget",IF(C20>B20*0.9,"Watch","On Track"))) | H20: =IF(C20=0,"No bank expenses imported",IF(D20<0,"Reduce or reallocate "&TEXT(-D20,"$#,##0"),"Available "&TEXT(D20,"$#,##0")))

Sheet Goals
A1: SAVINGS GOALS & FEASIBILITY
A3: Goal | B3: Priority | C3: Target Amount ($) | D3: Current Saved ($) | E3: Target Date | F3: Months Remaining | G3: Required Monthly ($) | H3: Planned Monthly ($) | I3: Projected Completion | J3: Status | K3: Monthly Gap ($) | L3: Notes
A4: Emergency Fund | B4: Critical | F4: =IF(E4="","",MAX(0,DATEDIF(Setup!$B$4,E4,"m"))) | G4: =IF(OR(C4="",F4=""),0,MAX(0,(C4-D4)/MAX(1,F4))) | I4: =IF(H4<=0,"",EDATE(Setup!$B$4,ROUNDUP(MAX(0,C4-D4)/H4,0))) | J4: =IF(C4="","",IF(D4>=C4,"Complete",IF(H4>=G4,"On Track",IF(H4>0,"Behind","Not Funded")))) | K4: =MAX(0,G4-H4)
A5: Savings | B5: High | C5: 10000 | D5: 76.16 | E5: 46600 | F5: =IF(E5="","",MAX(0,DATEDIF(Setup!$B$4,E5,"m"))) | G5: 826.98667 | H5: 375 | I5: =IF(H5<=0,"",EDATE(Setup!$B$4,ROUNDUP(MAX(0,C5-D5)/H5,0))) | J5: Behind | K5: 451.98667
A6: Goal 3 | B6: Medium | F6: =IF(E6="","",MAX(0,DATEDIF(Setup!$B$4,E6,"m"))) | G6: 0 | I6: =IF(H6<=0,"",EDATE(Setup!$B$4,ROUNDUP(MAX(0,C6-D6)/H6,0))) | K6: 0
A7: Goal 4 | B7: Medium | F7: =IF(E7="","",MAX(0,DATEDIF(Setup!$B$4,E7,"m"))) | G7: 0 | I7: =IF(H7<=0,"",EDATE(Setup!$B$4,ROUNDUP(MAX(0,C7-D7)/H7,0))) | K7: 0
A8: Goal 5 | B8: Low | F8: =IF(E8="","",MAX(0,DATEDIF(Setup!$B$4,E8,"m"))) | G8: 0 | I8: =IF(H8<=0,"",EDATE(Setup!$B$4,ROUNDUP(MAX(0,C8-D8)/H8,0))) | K8: 0
A9: Goal 6 | B9: Low | F9: =IF(E9="","",MAX(0,DATEDIF(Setup!$B$4,E9,"m"))) | G9: 0 | I9: =IF(H9<=0,"",EDATE(Setup!$B$4,ROUNDUP(MAX(0,C9-D9)/H9,0))) | K9: 0

Sheet Debts
A1: DEBT PAYOFF & PAYMENT RECOMMENDATION
A3: Debt Name | B3: Type | C3: Current Balance ($) | D3: APR | E3: Minimum Payment ($) | F3: Due Day | G3: Promo End | H3: Strategy Rank | I3: Recommended Extra ($) | J3: Recommended Payment ($) | K3: Months to Payoff | L3: Projected Payoff | M3: Est. Interest ($) | N3: Notes
A4: Debt 1 | B4: Credit Card | H4: =IF(C4<=0,"",IF(Setup!$B$6="Avalanche",_xludf.RANK.EQ(D4,$D$4:$D$11,0),IF(Setup!$B$6="Snowball",_xludf.RANK.EQ(C4,$C$4:$C$11,1),_xludf.RANK.EQ(E4,$E$4:$E$11,0)))) | I4: =IF(H4=1,MAX(0,Dashboard!$B$10-Setup!$B$5),0) | J4: =MIN(C4,E4+I4) | K4: =IF(OR(C4<=0,J4<=0),"",IF(D4=0,ROUNDUP(C4/J4,0),ROUNDUP(NPER(D4/12,-J4,C4),0))) | L4: =IF(K4="","",EDATE(Setup!$B$4,K4)) | M4: =IF(K4="","",MAX(0,J4*K4-C4))
A5: Debt 2 | B5: Credit Card | H5: =IF(C5<=0,"",IF(Setup!$B$6="Avalanche",_xludf.RANK.EQ(D5,$D$4:$D$11,0),IF(Setup!$B$6="Snowball",_xludf.RANK.EQ(C5,$C$4:$C$11,1),_xludf.RANK.EQ(E5,$E$4:$E$11,0)))) | I5: =IF(H5=1,MAX(0,Dashboard!$B$10-Setup!$B$5),0) | J5: 0 | L5: =IF(K5="","",EDATE(Setup!$B$4,K5))
A6: Debt 3 | B6: Loan | H6: =IF(C6<=0,"",IF(Setup!$B$6="Avalanche",_xludf.RANK.EQ(D6,$D$4:$D$11,0),IF(Setup!$B$6="Snowball",_xludf.RANK.EQ(C6,$C$4:$C$11,1),_xludf.RANK.EQ(E6,$E$4:$E$11,0)))) | I6: =IF(H6=1,MAX(0,Dashboard!$B$10-Setup!$B$5),0) | J6: 0 | L6: =IF(K6="","",EDATE(Setup!$B$4,K6))
A7: Debt 4 | B7: Loan | H7: =IF(C7<=0,"",IF(Setup!$B$6="Avalanche",_xludf.RANK.EQ(D7,$D$4:$D$11,0),IF(Setup!$B$6="Snowball",_xludf.RANK.EQ(C7,$C$4:$C$11,1),_xludf.RANK.EQ(E7,$E$4:$E$11,0)))) | I7: =IF(H7=1,MAX(0,Dashboard!$B$10-Setup!$B$5),0) | J7: 0 | L7: =IF(K7="","",EDATE(Setup!$B$4,K7))
A8: Debt 5 | B8: Vehicle | H8: =IF(C8<=0,"",IF(Setup!$B$6="Avalanche",_xludf.RANK.EQ(D8,$D$4:$D$11,0),IF(Setup!$B$6="Snowball",_xludf.RANK.EQ(C8,$C$4:$C$11,1),_xludf.RANK.EQ(E8,$E$4:$E$11,0)))) | I8: =IF(H8=1,MAX(0,Dashboard!$B$10-Setup!$B$5),0) | J8: 0 | L8: =IF(K8="","",EDATE(Setup!$B$4,K8))
A9: Debt 6 | B9: Medical | H9: =IF(C9<=0,"",IF(Setup!$B$6="Avalanche",_xludf.RANK.EQ(D9,$D$4:$D$11,0),IF(Setup!$B$6="Snowball",_xludf.RANK.EQ(C9,$C$4:$C$11,1),_xludf.RANK.EQ(E9,$E$4:$E$11,0)))) | I9: =IF(H9=1,MAX(0,Dashboard!$B$10-Setup!$B$5),0) | J9: 0 | L9: =IF(K9="","",EDATE(Setup!$B$4,K9))
A10: Debt 7 | B10: Other | H10: =IF(C10<=0,"",IF(Setup!$B$6="Avalanche",_xludf.RANK.EQ(D10,$D$4:$D$11,0),IF(Setup!$B$6="Snowball",_xludf.RANK.EQ(C10,$C$4:$C$11,1),_xludf.RANK.EQ(E10,$E$4:$E$11,0)))) | I10: =IF(H10=1,MAX(0,Dashboard!$B$10-Setup!$B$5),0) | J10: 0 | L10: =IF(K10="","",EDATE(Setup!$B$4,K10))
A11: Debt 8 | B11: Other | H11: =IF(C11<=0,"",IF(Setup!$B$6="Avalanche",_xludf.RANK.EQ(D11,$D$4:$D$11,0),IF(Setup!$B$6="Snowball",_xludf.RANK.EQ(C11,$C$4:$C$11,1),_xludf.RANK.EQ(E11,$E$4:$E$11,0)))) | I11: =IF(H11=1,MAX(0,Dashboard!$B$10-Setup!$B$5),0) | J11: 0 | L11: =IF(K11="","",EDATE(Setup!$B$4,K11))
A13: Debt Summary | B13: Value
A14: Total Debt | B14: =SUM(C4:C11)
A15: Total Minimum Payments | B15: =SUM(E4:E11)

Sheet Reconciliation
A1: MONTH-END BANK RECONCILIATION
A3: Category | B3: Manual Actual ($) | C3: Bank Actual ($) | D3: Difference ($) | E3: Difference % | F3: Status | G3: Action
A4: Housing | B4: =SUMIFS('Manual Actuals'!$C$2:$C$861,'Manual Actuals'!$D$2:$D$861,$A4,'Manual Actuals'!$H$2:$H$861,Setup!$B$4,'Manual Actuals'!$G$2:$G$861,"Yes") | C4: =SUMIFS(bk_download!$L$2:$L$1902,bk_download!$H$2:$H$1902,$A4,bk_download!$K$2:$K$1902,Setup!$B$4,bk_download!$J$2:$J$1902,"Yes") | D4: =B4-C4 | E4: =IF(C4=0,IF(B4=0,0,1),D4/C4) | F4: =IF(ABS(D4)<=1,"Matched",IF(ABS(D4)<=10,"Review","Investigate")) | G4: =IF(F4="Matched","None",IF(D4>0,"Manual exceeds bank","Bank exceeds manual"))
A5: Utilities | B5: =SUMIFS('Manual Actuals'!$C$2:$C$861,'Manual Actuals'!$D$2:$D$861,$A5,'Manual Actuals'!$H$2:$H$861,Setup!$B$4,'Manual Actuals'!$G$2:$G$861,"Yes") | C5: =SUMIFS(bk_download!$L$2:$L$1902,bk_download!$H$2:$H$1902,$A5,bk_download!$K$2:$K$1902,Setup!$B$4,bk_download!$J$2:$J$1902,"Yes") | D5: =B5-C5 | E5: =IF(C5=0,IF(B5=0,0,1),D5/C5) | F5: =IF(ABS(D5)<=1,"Matched",IF(ABS(D5)<=10,"Review","Investigate")) | G5: =IF(F5="Matched","None",IF(D5>0,"Manual exceeds bank","Bank exceeds manual"))
A6: Vehicle | B6: =SUMIFS('Manual Actuals'!$C$2:$C$861,'Manual Actuals'!$D$2:$D$861,$A6,'Manual Actuals'!$H$2:$H$861,Setup!$B$4,'Manual Actuals'!$G$2:$G$861,"Yes") | C6: =SUMIFS(bk_download!$L$2:$L$1902,bk_download!$H$2:$H$1902,$A6,bk_download!$K$2:$K$1902,Setup!$B$4,bk_download!$J$2:$J$1902,"Yes") | D6: =B6-C6 | E6: =IF(C6=0,IF(B6=0,0,1),D6/C6) | F6: =IF(ABS(D6)<=1,"Matched",IF(ABS(D6)<=10,"Review","Investigate")) | G6: =IF(F6="Matched","None",IF(D6>0,"Manual exceeds bank","Bank exceeds manual"))
A7: Food | B7: =SUMIFS('Manual Actuals'!$C$2:$C$861,'Manual Actuals'!$D$2:$D$861,$A7,'Manual Actuals'!$H$2:$H$861,Setup!$B$4,'Manual Actuals'!$G$2:$G$861,"Yes") | C7: =SUMIFS(bk_download!$L$2:$L$1902,bk_download!$H$2:$H$1902,$A7,bk_download!$K$2:$K$1902,Setup!$B$4,bk_download!$J$2:$J$1902,"Yes") | D7: =B7-C7 | E7: =IF(C7=0,IF(B7=0,0,1),D7/C7) | F7: =IF(ABS(D7)<=1,"Matched",IF(ABS(D7)<=10,"Review","Investigate")) | G7: =IF(F7="Matched","None",IF(D7>0,"Manual exceeds bank","Bank exceeds manual"))
A8: Insurance | B8: =SUMIFS('Manual Actuals'!$C$2:$C$861,'Manual Actuals'!$D$2:$D$861,$A8,'Manual Actuals'!$H$2:$H$861,Setup!$B$4,'Manual Actuals'!$G$2:$G$861,"Yes") | C8: =SUMIFS(bk_download!$L$2:$L$1902,bk_download!$H$2:$H$1902,$A8,bk_download!$K$2:$K$1902,Setup!$B$4,bk_download!$J$2:$J$1902,"Yes") | D8: =B8-C8 | E8: =IF(C8=0,IF(B8=0,0,1),D8/C8) | F8: =IF(ABS(D8)<=1,"Matched",IF(ABS(D8)<=10,"Review","Investigate")) | G8: =IF(F8="Matched","None",IF(D8>0,"Manual exceeds bank","Bank exceeds manual"))
A9: Medical | B9: =SUMIFS('Manual Actuals'!$C$2:$C$861,'Manual Actuals'!$D$2:$D$861,$A9,'Manual Actuals'!$H$2:$H$861,Setup!$B$4,'Manual Actuals'!$G$2:$G$861,"Yes") | C9: =SUMIFS(bk_download!$L$2:$L$1902,bk_download!$H$2:$H$1902,$A9,bk_download!$K$2:$K$1902,Setup!$B$4,bk_download!$J$2:$J$1902,"Yes") | D9: =B9-C9 | E9: =IF(C9=0,IF(B9=0,0,1),D9/C9) | F9: =IF(ABS(D9)<=1,"Matched",IF(ABS(D9)<=10,"Review","Investigate")) | G9: =IF(F9="Matched","None",IF(D9>0,"Manual exceeds bank","Bank exceeds manual"))
A10: Children | B10: =SUMIFS('Manual Actuals'!$C$2:$C$861,'Manual Actuals'!$D$2:$D$861,$A10,'Manual Actuals'!$H$2:$H$861,Setup!$B$4,'Manual Actuals'!$G$2:$G$861,"Yes") | C10: =SUMIFS(bk_download!$L$2:$L$1902,bk_download!$H$2:$H$1902,$A10,bk_download!$K$2:$K$1902,Setup!$B$4,bk_download!$J$2:$J$1902,"Yes") | D10: =B10-C10 | E10: =IF(C10=0,IF(B10=0,0,1),D10/C10) | F10: =IF(ABS(D10)<=1,"Matched",IF(ABS(D10)<=10,"Review","Investigate")) | G10: =IF(F10="Matched","None",IF(D10>0,"Manual exceeds bank","Bank exceeds manual"))
A11: Personal Care | B11: =SUMIFS('Manual Actuals'!$C$2:$C$861,'Manual Actuals'!$D$2:$D$861,$A11,'Manual Actuals'!$H$2:$H$861,Setup!$B$4,'Manual Actuals'!$G$2:$G$861,"Yes") | C11: =SUMIFS(bk_download!$L$2:$L$1902,bk_download!$H$2:$H$1902,$A11,bk_download!$K$2:$K$1902,Setup!$B$4,bk_download!$J$2:$J$1902,"Yes") | D11: =B11-C11 | E11: =IF(C11=0,IF(B11=0,0,1),D11/C11) | F11: =IF(ABS(D11)<=1,"Matched",IF(ABS(D11)<=10,"Review","Investigate")) | G11: =IF(F11="Matched","None",IF(D11>0,"Manual exceeds bank","Bank exceeds manual"))
A12: Entertainment | B12: =SUMIFS('Manual Actuals'!$C$2:$C$861,'Manual Actuals'!$D$2:$D$861,$A12,'Manual Actuals'!$H$2:$H$861,Setup!$B$4,'Manual Actuals'!$G$2:$G$861,"Yes") | C12: =SUMIFS(bk_download!$L$2:$L$1902,bk_download!$H$2:$H$1902,$A12,bk_download!$K$2:$K$1902,Setup!$B$4,bk_download!$J$2:$J$1902,"Yes") | D12: =B12-C12 | E12: =IF(C12=0,IF(B12=0,0,1),D12/C12) | F12: =IF(ABS(D12)<=1,"Matched",IF(ABS(D12)<=10,"Review","Investigate")) | G12: =IF(F12="Matched","None",IF(D12>0,"Manual exceeds bank","Bank exceeds manual"))
A13: Giving | B13: =SUMIFS('Manual Actuals'!$C$2:$C$861,'Manual Actuals'!$D$2:$D$861,$A13,'Manual Actuals'!$H$2:$H$861,Setup!$B$4,'Manual Actuals'!$G$2:$G$861,"Yes") | C13: =SUMIFS(bk_download!$L$2:$L$1902,bk_download!$H$2:$H$1902,$A13,bk_download!$K$2:$K$1902,Setup!$B$4,bk_download!$J$2:$J$1902,"Yes") | D13: =B13-C13 | E13: =IF(C13=0,IF(B13=0,0,1),D13/C13) | F13: =IF(ABS(D13)<=1,"Matched",IF(ABS(D13)<=10,"Review","Investigate")) | G13: =IF(F13="Matched","None",IF(D13>0,"Manual exceeds bank","Bank exceeds manual"))
A14: Subscriptions | B14: =SUMIF('Budget Plan'!$A$4:$A$60,"Subscriptions",'Budget Plan'!$K$4:$K$60) | C14: =SUMIFS(bk_download!$L$2:$L$1902,bk_download!$H$2:$H$1902,$A14,bk_download!$K$2:$K$1902,Setup!$B$4,bk_download!$J$2:$J$1902,"Yes") | D14: =B14-C14 | E14: =IF(B14=0,IF(C14=0,0,1),ABS(D14)/B14) | F14: =IF(D14=0,"Matched",IF(ABS(E14)<=0.05,"Close","Investigate")) | G14: =IF(F14="Matched","None",IF(D14>0,"Manual exceeds bank","Bank exceeds manual"))
A15: Pets | B15: =SUMIFS('Manual Actuals'!$C$2:$C$861,'Manual Actuals'!$D$2:$D$861,$A15,'Manual Actuals'!$H$2:$H$861,Setup!$B$4,'Manual Actuals'!$G$2:$G$861,"Yes") | C15: =SUMIFS(bk_download!$L$2:$L$1902,bk_download!$H$2:$H$1902,$A15,bk_download!$K$2:$K$1902,Setup!$B$4,bk_download!$J$2:$J$1902,"Yes") | D15: =B15-C15 | E15: =IF(C15=0,IF(B15=0,0,1),D15/C15) | F15: =IF(ABS(D15)<=1,"Matched",IF(ABS(D15)<=10,"Review","Investigate")) | G15: =IF(F15="Matched","None",IF(D15>0,"Manual exceeds bank","Bank exceeds manual"))
A16: Debt | B16: =SUMIFS('Manual Actuals'!$C$2:$C$861,'Manual Actuals'!$D$2:$D$861,$A16,'Manual Actuals'!$H$2:$H$861,Setup!$B$4,'Manual Actuals'!$G$2:$G$861,"Yes") | C16: =SUMIFS(bk_download!$L$2:$L$1902,bk_download!$H$2:$H$1902,$A16,bk_download!$K$2:$K$1902,Setup!$B$4,bk_download!$J$2:$J$1902,"Yes") | D16: =B16-C16 | E16: =IF(C16=0,IF(B16=0,0,1),D16/C16) | F16: =IF(ABS(D16)<=1,"Matched",IF(ABS(D16)<=10,"Review","Investigate")) | G16: =IF(F16="Matched","None",IF(D16>0,"Manual exceeds bank","Bank exceeds manual"))
A17: Savings | B17: =SUMIFS('Manual Actuals'!$C$2:$C$861,'Manual Actuals'!$D$2:$D$861,$A17,'Manual Actuals'!$H$2:$H$861,Setup!$B$4,'Manual Actuals'!$G$2:$G$861,"Yes") | C17: =SUMIFS(bk_download!$L$2:$L$1902,bk_download!$H$2:$H$1902,$A17,bk_download!$K$2:$K$1902,Setup!$B$4,bk_download!$J$2:$J$1902,"Yes") | D17: =B17-C17 | E17: =IF(C17=0,IF(B17=0,0,1),D17/C17) | F17: =IF(ABS(D17)<=1,"Matched",IF(ABS(D17)<=10,"Review","Investigate")) | G17: =IF(F17="Matched","None",IF(D17>0,"Manual exceeds bank","Bank exceeds manual"))
